#VRML_SIM R2023b utf8
# license: Apache License 2.0
# license url: http://www.apache.org/licenses/LICENSE-2.0
# This is a proto file for Webots for the wheelchair
# Extracted from: D:\model.urdf

PROTO wheelchair [
  field  SFVec3f     translation     0 0 0
  field  SFRotation  rotation        0 0 1 0
  field  SFString    name            "wheelchair"  # Is `Robot.name`.
  field  SFString    controller      "void"        # Is `Robot.controller`.
  field  MFString    controllerArgs  []            # Is `Robot.controllerArgs`.
  field  SFString    customData      ""            # Is `Robot.customData`.
  field  SFBool      supervisor      FALSE         # Is `Robot.supervisor`.
  field  SFBool      synchronization TRUE          # Is `Robot.synchronization`.
  field  SFBool      selfCollision   FALSE         # Is `Robot.selfCollision`.
]
{
  Robot {
    translation IS translation
    rotation IS rotation
    controller IS controller
    controllerArgs IS controllerArgs
    customData IS customData
    supervisor IS supervisor
    synchronization IS synchronization
    selfCollision IS selfCollision
    children [
      Shape {
        appearance PBRAppearance {
          baseColor 0.500000 0.500000 0.500000
          roughness 1.000000
          metalness 0
        }
        geometry Box {
           size 0.001000 0.001000 0.001000
        }
      }
      Solid {
        translation 0.000000 0.000000 0.700000
        children [
          Shape {
            appearance DEF white PBRAppearance {
              roughness 1.000000
              metalness 0
            }
            geometry Box {
               size 0.812000 0.643000 1.191000
            }
          }
          Solid {
            rotation 1.000000 0.000000 -0.000000 3.141593
            children [
              Shape {
                appearance PBRAppearance {
                  baseColor 0.500000 0.500000 0.500000
                  roughness 1.000000
                  metalness 0
                }
                geometry Box {
                   size 0.010000 0.010000 0.010000
                }
              }
            ]
            name "imu_link"
            physics Physics {
              density -1
              mass 0.010000
              centerOfMass [ 0.000000 0.000000 0.000000 ]
              inertiaMatrix [
                1.000000e-06 1.000000e-06 1.000000e-06
                0.000000e+00 0.000000e+00 0.000000e+00
              ]
            }
          }
          Solid {
            translation 0.609200 0.000000 -0.392300
            children [
              Shape {
                appearance USE white
                geometry Box {
                   size 0.406400 0.406400 0.406400
                }
              }
            ]
            name "legs"
            boundingObject Box {
               size 0.406400 0.406400 0.406400
            }
            physics Physics {
              density -1
              mass 2.000000
              centerOfMass [ 0.000000 0.000000 0.000000 ]
              inertiaMatrix [
                1.354667e-01 1.354667e-01 1.354667e-01
                0.000000e+00 0.000000e+00 0.000000e+00
              ]
            }
          }
          Solid {
            translation 0.000000 0.321500 -0.446625
            children [
              Shape {
                appearance USE white
                geometry Box {
                   size 1.015000 0.160750 0.148875
                }
              }
              HingeJoint {
                jointParameters HingeJointParameters {
                  axis 0.000000 1.000000 -0.000046
                  anchor 0.000000 0.000000 -0.072875
                }
                device [
                  RotationalMotor {
                    name "right_main_wheel_joint"
                    maxTorque 10000
                  }
                  PositionSensor {
                    name "right_main_wheel_joint_sensor"
                  }
                ]
                endPoint Solid {
                  translation 0.000000 0.000000 -0.072875
                  rotation 1.000000 0.000000 0.000000 1.570750
                  children [
                    Shape {
                      appearance USE white
                      geometry Cylinder {
                        radius 0.165
                        height 0.065
                      }
                    }
                  ]
                  name "right_main_wheel"
                  boundingObject Cylinder {
                    radius 0.165
                    height 0.065
                  }
                  physics Physics {
                    density -1
                    mass 2.000000
                    centerOfMass [ 0.000000 0.000000 0.000000 ]
                    inertiaMatrix [
                      1.431667e-02 1.431667e-02 2.722500e-02
                      0.000000e+00 0.000000e+00 0.000000e+00
                    ]
                  }
                }
              }
              Solid {
                translation 0.482500 0.025000 0.124438
                rotation 0.000000 0.000000 1.000000 1.570700
                children [
                  Shape {
                    appearance PBRAppearance {
                      baseColor 0.500000 0.500000 0.500000
                      roughness 1.000000
                      metalness 0
                    }
                    geometry Box {
                       size 0.050000 0.050000 0.100000
                    }
                  }
                  Lidar {
                    name "head_hokuyo_sensor"
                    fieldOfView 3.926983
                    horizontalResolution 720
                    numberOfLayers 1
                    minRange 0.200000
                    maxRange 10.100000
                    noise 0.001980
                    resolution 0.010000
                  }
                ]
                name "right_scanner"
                boundingObject Box {
                   size 0.050000 0.050000 0.100000
                }
                physics Physics {
                  density -1
                  mass 0.000010
                  centerOfMass [ 0.000000 0.000000 0.000000 ]
                  inertiaMatrix [
                    1.000000e-03 1.000000e-03 1.000000e-03
                    0.000000e+00 0.000000e+00 0.000000e+00
                  ]
                }
              }
              HingeJoint {
                jointParameters HingeJointParameters {
                  axis 0.000000 0.000000 1.000000
                  anchor -0.406000 0.000000 -0.148875
                  staticFriction 0.5
                }
                device [
                  RotationalMotor {
                    name "front_right_swivel_joint"
                    maxTorque 10000
                  }
                  PositionSensor {
                    name "front_right_swivel_joint_sensor"
                  }
                ]
                endPoint Solid {
                  translation -0.406000 0.000000 -0.148875
                  children [
                    Shape {
                      appearance USE white
                      geometry Cylinder {
                        radius 0.01
                        height 0.065
                      }
                    }
                    HingeJoint {
                      jointParameters HingeJointParameters {
                        axis 0.000000 -1.000000 0.000046
                        anchor 0.065000 0.000000 0.000000
                        staticFriction 0.5
                      }
                      device [
                        RotationalMotor {
                          name "front_right_wheel_joint"
                          maxTorque 10000
                        }
                        PositionSensor {
                          name "front_right_wheel_joint_sensor"
                        }
                      ]
                      endPoint Solid {
                        translation 0.065000 0.000000 0.000000
                        rotation 1.000000 0.000000 0.000000 1.570750
                        children [
                          Shape {
                            appearance USE white
                            geometry Cylinder {
                              radius 0.089
                              height 0.05
                            }
                          }
                        ]
                        name "front_right_wheel"
                        boundingObject Cylinder {
                          radius 0.089
                          height 0.05
                        }
                        physics Physics {
                          density -1
                          mass 1.000000
                          centerOfMass [ 0.000000 0.000000 0.000000 ]
                          inertiaMatrix [
                            2.188583e-03 2.188583e-03 3.960500e-03
                            0.000000e+00 0.000000e+00 0.000000e+00
                          ]
                        }
                      }
                    }
                  ]
                  name "front_right_swivel"
                  boundingObject Cylinder {
                    radius 0.01
                    height 0.065
                  }
                  physics Physics {
                    density -1
                    mass 0.100000
                    centerOfMass [ 0.000000 0.000000 0.000000 ]
                    inertiaMatrix [
                      3.770833e-05 3.770833e-05 5.000000e-06
                      0.000000e+00 0.000000e+00 0.000000e+00
                    ]
                  }
                }
              }
              HingeJoint {
                jointParameters HingeJointParameters {
                  axis 0.000000 0.000000 1.000000
                  anchor 0.406000 0.000000 -0.148875
                  staticFriction 0.5
                }
                device [
                  RotationalMotor {
                    name "rear_right_swivel_joint"
                    maxTorque 10000
                  }
                  PositionSensor {
                    name "rear_right_swivel_joint_sensor"
                  }
                ]
                endPoint Solid {
                  translation 0.406000 0.000000 -0.148875
                  children [
                    Shape {
                      appearance USE white
                      geometry Cylinder {
                        radius 0.01
                        height 0.065
                      }
                    }
                    HingeJoint {
                      jointParameters HingeJointParameters {
                        axis 0.000000 -1.000000 0.000046
                        anchor 0.065000 0.000000 0.000000
                        staticFriction 0.5
                      }
                      device [
                        RotationalMotor {
                          name "rear_right_wheel_joint"
                          maxTorque 10000
                        }
                        PositionSensor {
                          name "rear_right_wheel_joint_sensor"
                        }
                      ]
                      endPoint Solid {
                        translation 0.065000 0.000000 0.000000
                        rotation 1.000000 0.000000 0.000000 1.570750
                        children [
                          Shape {
                            appearance USE white
                            geometry Cylinder {
                              radius 0.089
                              height 0.05
                            }
                          }
                        ]
                        name "rear_right_wheel"
                        boundingObject Cylinder {
                          radius 0.089
                          height 0.05
                        }
                        physics Physics {
                          density -1
                          mass 1.000000
                          centerOfMass [ 0.000000 0.000000 0.000000 ]
                          inertiaMatrix [
                            2.188583e-03 2.188583e-03 3.960500e-03
                            0.000000e+00 0.000000e+00 0.000000e+00
                          ]
                        }
                      }
                    }
                  ]
                  name "rear_right_swivel"
                  boundingObject Cylinder {
                    radius 0.01
                    height 0.065
                  }
                  physics Physics {
                    density -1
                    mass 0.100000
                    centerOfMass [ 0.000000 0.000000 0.000000 ]
                    inertiaMatrix [
                      3.770833e-05 3.770833e-05 5.000000e-06
                      0.000000e+00 0.000000e+00 0.000000e+00
                    ]
                  }
                }
              }
            ]
            name "right_bar"
            boundingObject Box {
               size 1.015000 0.160750 0.148875
            }
            physics Physics {
              density -1
              mass 2.000000
              centerOfMass [ 0.000000 0.000000 0.000000 ]
            }
          }
          Solid {
            translation 0.000000 -0.321500 -0.446625
            children [
              Shape {
                appearance USE white
                geometry Box {
                   size 1.015000 0.160750 0.148875
                }
              }
              HingeJoint {
                jointParameters HingeJointParameters {
                  axis 0.000000 1.000000 -0.000046
                  anchor 0.000000 0.000000 -0.072875
                }
                device [
                  RotationalMotor {
                    name "left_main_wheel_joint"
                    maxTorque 10000
                  }
                  PositionSensor {
                    name "left_main_wheel_joint_sensor"
                  }
                ]
                endPoint Solid {
                  translation 0.000000 0.000000 -0.072875
                  rotation 1.000000 0.000000 0.000000 1.570750
                  children [
                    Shape {
                      appearance USE white
                      geometry Cylinder {
                        radius 0.165
                        height 0.065
                      }
                    }
                  ]
                  name "left_main_wheel"
                  boundingObject Cylinder {
                    radius 0.165
                    height 0.065
                  }
                  physics Physics {
                    density -1
                    mass 2.000000
                    centerOfMass [ 0.000000 0.000000 0.000000 ]
                    inertiaMatrix [
                      1.431667e-02 1.431667e-02 2.722500e-02
                      0.000000e+00 0.000000e+00 0.000000e+00
                    ]
                  }
                }
              }
              Solid {
                translation 0.482500 -0.025000 0.124438
                rotation 0.000000 0.000000 -1.000000 1.570700
                children [
                  Shape {
                    appearance PBRAppearance {
                      baseColor 0.500000 0.500000 0.500000
                      roughness 1.000000
                      metalness 0
                    }
                    geometry Box {
                       size 0.050000 0.050000 0.100000
                    }
                  }
                  Lidar {
                    name "head_hokuyo_sensor2"
                    fieldOfView 3.926983
                    horizontalResolution 720
                    numberOfLayers 1
                    minRange 0.200000
                    maxRange 10.100000
                    noise 0.001980
                    resolution 0.010000
                  }
                ]
                name "left_scanner"
                boundingObject Box {
                   size 0.050000 0.050000 0.100000
                }
                physics Physics {
                  density -1
                  mass 0.000010
                  centerOfMass [ 0.000000 0.000000 0.000000 ]
                  inertiaMatrix [
                    1.000000e-03 1.000000e-03 1.000000e-03
                    0.000000e+00 0.000000e+00 0.000000e+00
                  ]
                }
              }
              HingeJoint {
                jointParameters HingeJointParameters {
                  axis 0.000000 0.000000 1.000000
                  anchor -0.406000 0.000000 -0.148875
                  staticFriction 0.5
                }
                device [
                  RotationalMotor {
                    name "front_left_swivel_joint"
                    maxTorque 10000
                  }
                  PositionSensor {
                    name "front_left_swivel_joint_sensor"
                  }
                ]
                endPoint Solid {
                  translation -0.406000 0.000000 -0.148875
                  children [
                    Shape {
                      appearance USE white
                      geometry Cylinder {
                        radius 0.01
                        height 0.065
                      }
                    }
                    HingeJoint {
                      jointParameters HingeJointParameters {
                        axis 0.000000 -1.000000 0.000046
                        anchor 0.065000 0.000000 0.000000
                        staticFriction 0.5
                      }
                      device [
                        RotationalMotor {
                          name "front_left_wheel_joint"
                          maxTorque 10000
                        }
                        PositionSensor {
                          name "front_left_wheel_joint_sensor"
                        }
                      ]
                      endPoint Solid {
                        translation 0.065000 0.000000 0.000000
                        rotation 1.000000 0.000000 0.000000 1.570750
                        children [
                          Shape {
                            appearance USE white
                            geometry Cylinder {
                              radius 0.089
                              height 0.05
                            }
                          }
                        ]
                        name "front_left_wheel"
                        boundingObject Cylinder {
                          radius 0.089
                          height 0.05
                        }
                        physics Physics {
                          density -1
                          mass 1.000000
                          centerOfMass [ 0.000000 0.000000 0.000000 ]
                          inertiaMatrix [
                            2.188583e-03 2.188583e-03 3.960500e-03
                            0.000000e+00 0.000000e+00 0.000000e+00
                          ]
                        }
                      }
                    }
                  ]
                  name "front_left_swivel"
                  boundingObject Cylinder {
                    radius 0.01
                    height 0.065
                  }
                  physics Physics {
                    density -1
                    mass 0.100000
                    centerOfMass [ 0.000000 0.000000 0.000000 ]
                    inertiaMatrix [
                      3.770833e-05 3.770833e-05 5.000000e-06
                      0.000000e+00 0.000000e+00 0.000000e+00
                    ]
                  }
                }
              }
              HingeJoint {
                jointParameters HingeJointParameters {
                  axis 0.000000 0.000000 1.000000
                  anchor 0.406000 0.000000 -0.148875
                  staticFriction 0.5
                }
                device [
                  RotationalMotor {
                    name "rear_left_swivel_joint"
                    maxTorque 10000
                  }
                  PositionSensor {
                    name "rear_left_swivel_joint_sensor"
                  }
                ]
                endPoint Solid {
                  translation 0.406000 0.000000 -0.148875
                  children [
                    Shape {
                      appearance USE white
                      geometry Cylinder {
                        radius 0.01
                        height 0.065
                      }
                    }
                    HingeJoint {
                      jointParameters HingeJointParameters {
                        axis 0.000000 -1.000000 0.000046
                        anchor 0.065000 0.000000 0.000000
                        staticFriction 0.5
                      }
                      device [
                        RotationalMotor {
                          name "rear_left_wheel_joint"
                          maxTorque 10000
                        }
                        PositionSensor {
                          name "rear_left_wheel_joint_sensor"
                        }
                      ]
                      endPoint Solid {
                        translation 0.065000 0.000000 0.000000
                        rotation 1.000000 0.000000 0.000000 1.570750
                        children [
                          Shape {
                            appearance USE white
                            geometry Cylinder {
                              radius 0.089
                              height 0.05
                            }
                          }
                        ]
                        name "rear_left_wheel"
                        boundingObject Cylinder {
                          radius 0.089
                          height 0.05
                        }
                        physics Physics {
                          density -1
                          mass 1.000000
                          centerOfMass [ 0.000000 0.000000 0.000000 ]
                        }
                      }
                    }
                  ]
                  name "rear_left_swivel"
                  boundingObject Cylinder {
                    radius 0.01
                    height 0.065
                  }
                  physics Physics {
                    density -1
                    mass 0.100000
                    centerOfMass [ 0.000000 0.000000 0.000000 ]
                  }
                }
              }
            ]
            name "left_bar"
            boundingObject Box {
               size 1.015000 0.160750 0.148875
            }
            physics Physics {
              density -1
              mass 2.000000
              centerOfMass [ 0.000000 0.000000 0.000000 ]
            }
          }
        ]
        name "base_link"
        boundingObject Box {
           size 0.812000 0.643000 1.191000
        }
        physics Physics {
          density -1
          mass 10.000000
          centerOfMass [ 0.000000 0.000000 0.000000 ]
          inertiaMatrix [
            1.669167e+00 1.212500e+00 1.528333e+00
            0.000000e+00 0.000000e+00 0.000000e+00
          ]
        }
      }
    ]
    name IS name
  }
}
